<robot name="learm">
    <link name="arm_base_link">
        <inertial>
            <mass value="0.0342685"/>
            <origin xyz="0 0 0" rpy="0 -0 0"/>
            <inertia ixx="1.7991e-05" ixy="0" ixz="0" iyy="1.7991e-05" iyz="0" izz="1.54208e-05"/>
        </inertial>
        <visual>
            <origin xyz="0 0 0" rpy="0 -0 0"/>
            <geometry>
                <mesh filename="package://ardupilot_gz_description/models/learm/meshes/base.dae" scale="1 1 1"/>
            </geometry>
            <material name="arm_base_linkarm_base_link_visual">
                <texture/>
                <color rgba="0.12 0.12 0.12 1.2"/>
            </material>
        </visual>
        <collision>
            <origin xyz="0 0 0.032" rpy="0 -0 0"/>
            <geometry>
                <cylinder radius="0.06" length="0.08"/>
            </geometry>
        </collision>
    </link>
    <link name="finger_left_link">
        <inertial>
            <mass value="0.00303"/>
            <origin xyz="-1.33705e-17 -0.01 0.025" rpy="5.02256e-34 2.02931e-17 -4.57939e-34"/>
            <inertia ixx="9.3425e-07" ixy="0" ixz="0" iyy="9.15313e-07" iyz="0" izz="3.15625e-08"/>
        </inertial>
        <visual>
            <origin xyz="-2.77556e-17 1.38778e-17 2.81623e-34" rpy="1.00451e-33 4.05861e-17 -9.15878e-34"/>
            <geometry>
                <mesh filename="package://ardupilot_gz_description/models/learm/meshes/finger.dae" scale="1 1 1"/>
            </geometry>
            <material name="finger_left_linkfinger_left_link_visual">
                <texture/>
                <color rgba="0.12 0.12 0.12 1.2"/>
            </material>
        </visual>
        <collision>
            <origin xyz="-2.77556e-17 1.38778e-17 2.81623e-34" rpy="1.00451e-33 4.05861e-17 -9.15878e-34"/>
            <geometry>
                <mesh filename="package://ardupilot_gz_description/models/learm/meshes/finger_lowpoly.stl" scale="1 1 1"/>
            </geometry>
        </collision>
    </link>
    <link name="finger_right_link">
        <inertial>
            <mass value="0.00303"/>
            <origin xyz="-1.33705e-17 0.01 0.025" rpy="-5.02256e-34 2.02931e-17 4.57939e-34"/>
            <inertia ixx="9.3425e-07" ixy="0" ixz="0" iyy="9.15313e-07" iyz="0" izz="3.15625e-08"/>
        </inertial>
        <visual>
            <origin xyz="-2.77556e-17 -1.38778e-17 2.81623e-34" rpy="1.07699e-22 -4.05861e-17 3.14159"/>
            <geometry>
                <mesh filename="package://ardupilot_gz_description/models/learm/meshes/finger.dae" scale="1 1 1"/>
            </geometry>
            <material name="finger_right_linkfinger_right_link_visual">
                <texture/>
                <color rgba="0.12 0.12 0.12 1.2"/>
            </material>
        </visual>
        <collision>
            <origin xyz="-2.77556e-17 -1.38778e-17 2.81623e-34" rpy="1.07699e-22 -4.05861e-17 3.14159"/>
            <geometry>
                <mesh filename="package://ardupilot_gz_description/models/learm/meshes/finger_lowpoly.stl" scale="1 1 1"/>
            </geometry>
        </collision>
    </link>
    <link name="forearm_link">
        <inertial>
            <mass value="0.03636"/>
            <origin xyz="6.08792e-19 0 0.03" rpy="0 2.02931e-17 0"/>
            <inertia ixx="1.5756e-05" ixy="0" ixz="0" iyy="1.28018e-05" iyz="0" izz="6.74175e-06"/>
        </inertial>
        <visual>
            <origin xyz="2.81623e-34 0 2.77556e-17" rpy="0 4.05861e-17 0"/>
            <geometry>
                <mesh filename="package://ardupilot_gz_description/models/learm/meshes/forearm.dae" scale="1 1 1"/>
            </geometry>
            <material name="forearm_linkforearm_link_visual">
                <texture/>
                <color rgba="0.12 0.12 0.12 1.2"/>
            </material>
        </visual>
        <collision>
            <origin xyz="2.81623e-34 0 2.77556e-17" rpy="0 4.05861e-17 0"/>
            <geometry>
                <mesh filename="package://ardupilot_gz_description/models/learm/meshes/forearm_lowpoly.stl" scale="1 1 1"/>
            </geometry>
        </collision>
    </link>
    <link name="grip_left_link">
        <inertial>
            <mass value="0.0037875"/>
            <origin xyz="-1.66693e-16 -1.6661e-16 0.01" rpy="7.68484e-18 -1.59098e-17 4.78263e-17"/>
            <inertia ixx="8.60078e-07" ixy="0" ixz="0" iyy="7.96953e-07" iyz="0" izz="7.89063e-08"/>
        </inertial>
        <visual>
            <origin xyz="-3.33067e-16 -3.33067e-16 -1.73472e-17" rpy="1.53697e-17 -3.18197e-17 9.56526e-17"/>
            <geometry>
                <mesh filename="package://ardupilot_gz_description/models/learm/meshes/carpal_left.dae" scale="1 1 1"/>
            </geometry>
            <material name="grip_left_linkgrip_left_link_visual">
                <texture/>
                <color rgba="0.12 0.12 0.12 1.2"/>
            </material>
        </visual>
        <collision>
            <origin xyz="-3.33067e-16 -3.33067e-16 -1.73472e-17" rpy="1.53697e-17 -3.18197e-17 9.56526e-17"/>
            <geometry>
                <mesh filename="package://ardupilot_gz_description/models/learm/meshes/carpal_left_lowpoly.stl" scale="1 1 1"/>
            </geometry>
        </collision>
    </link>
    <link name="grip_right_link">
        <inertial>
            <mass value="0.0037875"/>
            <origin xyz="-1.66693e-16 1.11099e-16 0.01" rpy="-7.68484e-18 -1.59098e-17 -4.78263e-17"/>
            <inertia ixx="8.60078e-07" ixy="0" ixz="0" iyy="7.96953e-07" iyz="0" izz="7.89063e-08"/>
        </inertial>
        <visual>
            <origin xyz="-3.33067e-16 2.22045e-16 -6.245e-17" rpy="-1.53697e-17 -3.18197e-17 -9.56526e-17"/>
            <geometry>
                <mesh filename="package://ardupilot_gz_description/models/learm/meshes/carpal_right.dae" scale="1 1 1"/>
            </geometry>
            <material name="grip_right_linkgrip_right_link_visual">
                <texture/>
                <color rgba="0.12 0.12 0.12 1.2"/>
            </material>
        </visual>
        <collision>
            <origin xyz="-3.33067e-16 2.22045e-16 -6.245e-17" rpy="-1.53697e-17 -3.18197e-17 -9.56526e-17"/>
            <geometry>
                <mesh filename="package://ardupilot_gz_description/models/learm/meshes/carpal_right_lowpoly.stl" scale="1 1 1"/>
            </geometry>
        </collision>
    </link>
    <link name="hand_link">
        <inertial>
            <mass value="0.03232"/>
            <origin xyz="0.02 0 0.03" rpy="0 2.02931e-17 0"/>
            <inertia ixx="5.38667e-06" ixy="0" ixz="0" iyy="5.38667e-06" iyz="0" izz="8.61867e-06"/>
        </inertial>
        <visual>
            <origin xyz="-5.55112e-17 0 5.63246e-34" rpy="0 4.05861e-17 0"/>
            <geometry>
                <mesh filename="package://ardupilot_gz_description/models/learm/meshes/hand.dae" scale="1 1 1"/>
            </geometry>
            <material name="hand_linkhand_link_visual">
                <texture/>
                <color rgba="0.12 0.12 0.12 1.2"/>
            </material>
        </visual>
        <collision>
            <origin xyz="-5.55112e-17 0 5.63246e-34" rpy="0 4.05861e-17 0"/>
            <geometry>
                <mesh filename="package://ardupilot_gz_description/models/learm/meshes/hand_lowpoly.stl" scale="1 1 1"/>
            </geometry>
        </collision>
    </link>
    <link name="humerus_link">
        <inertial>
            <mass value="0.0198313"/>
            <origin xyz="8.11723e-19 0 0.04" rpy="0 2.02931e-17 0"/>
            <inertia ixx="2.23515e-05" ixy="0" ixz="0" iyy="1.92529e-05" iyz="0" izz="5.1644e-06"/>
        </inertial>
        <visual>
            <origin xyz="-7.04057e-35 0 -6.93889e-18" rpy="0 4.05861e-17 0"/>
            <geometry>
                <mesh filename="package://ardupilot_gz_description/models/learm/meshes/humerus.dae" scale="1 1 1"/>
            </geometry>
            <material name="humerus_linkhumerus_link_visual">
                <texture/>
                <color rgba="0.12 0.12 0.12 1.2"/>
            </material>
        </visual>
        <collision>
            <origin xyz="-7.04057e-35 0 -6.93889e-18" rpy="0 4.05861e-17 0"/>
            <geometry>
                <mesh filename="package://ardupilot_gz_description/models/learm/meshes/humerus_lowpoly.stl" scale="1 1 1"/>
            </geometry>
        </collision>
    </link>
    <link name="shoulder_link">
        <inertial>
            <mass value="0.0253841"/>
            <origin xyz="0 0 0" rpy="0 -0 0"/>
            <inertia ixx="1.14757e-05" ixy="0" ixz="0" iyy="1.14757e-05" iyz="0" izz="2.03073e-05"/>
        </inertial>
        <visual>
            <origin xyz="0 0 0" rpy="0 -0 0"/>
            <geometry>
                <mesh filename="package://ardupilot_gz_description/models/learm/meshes/shoulder.dae" scale="1 1 1"/>
            </geometry>
            <material name="shoulder_linkshoulder_link_visual">
                <texture/>
                <color rgba="0.12 0.12 0.12 1.2"/>
            </material>
        </visual>
        <collision>
            <origin xyz="0 0 0" rpy="0 -0 0"/>
            <geometry>
                <mesh filename="package://ardupilot_gz_description/models/learm/meshes/shoulder_lowpoly.stl" scale="1 1 1"/>
            </geometry>
        </collision>
    </link>
    <link name="tendon_left_link">
        <inertial>
            <mass value="0.00202"/>
            <origin xyz="-1.80729e-16 -1.66687e-16 0.02" rpy="7.68484e-18 -1.59098e-17 4.78263e-17"/>
            <inertia ixx="2.86167e-07" ixy="0" ixz="0" iyy="2.73542e-07" iyz="0" izz="2.10417e-08"/>
        </inertial>
        <visual>
            <origin xyz="-3.60822e-16 -3.33067e-16 -7.97973e-17" rpy="1.53697e-17 -3.18197e-17 9.56526e-17"/>
            <geometry>
                <mesh filename="package://ardupilot_gz_description/models/learm/meshes/tendon.dae" scale="1 1 1"/>
            </geometry>
            <material name="tendon_left_linktendon_left_link_visual">
                <texture/>
                <color rgba="0.12 0.12 0.12 1.2"/>
            </material>
        </visual>
        <collision>
            <origin xyz="-3.60822e-16 -3.33067e-16 -7.97973e-17" rpy="1.53697e-17 -3.18197e-17 9.56526e-17"/>
            <geometry>
                <mesh filename="package://ardupilot_gz_description/models/learm/meshes/tendon_lowpoly.stl" scale="1 1 1"/>
            </geometry>
        </collision>
    </link>
    <link name="tendon_right_link">
        <inertial>
            <mass value="0.00202"/>
            <origin xyz="-1.80729e-16 1.66687e-16 0.02" rpy="-7.68484e-18 -1.59098e-17 -4.78263e-17"/>
            <inertia ixx="2.86167e-07" ixy="0" ixz="0" iyy="2.73542e-07" iyz="0" izz="2.10417e-08"/>
        </inertial>
        <visual>
            <origin xyz="-3.60822e-16 3.33067e-16 -7.97973e-17" rpy="-1.53697e-17 -3.18197e-17 -9.56526e-17"/>
            <geometry>
                <mesh filename="package://ardupilot_gz_description/models/learm/meshes/tendon.dae" scale="1 1 1"/>
            </geometry>
            <material name="tendon_right_linktendon_right_link_visual">
                <texture/>
                <color rgba="0.12 0.12 0.12 1.2"/>
            </material>
        </visual>
        <collision>
            <origin xyz="-3.60822e-16 3.33067e-16 -7.97973e-17" rpy="-1.53697e-17 -3.18197e-17 -9.56526e-17"/>
            <geometry>
                <mesh filename="package://ardupilot_gz_description/models/learm/meshes/tendon_lowpoly.stl" scale="1 1 1"/>
            </geometry>
        </collision>
    </link>
    <link name="wrist_link">
        <inertial>
            <mass value="0.07272"/>
            <origin xyz="0.01 0 0.02" rpy="0 2.02931e-17 0"/>
            <inertia ixx="2.727e-05" ixy="0" ixz="0" iyy="3.1512e-05" iyz="0" izz="1.515e-05"/>
        </inertial>
        <visual>
            <origin xyz="2.77556e-17 0 -5.55112e-17" rpy="0 4.05861e-17 0"/>
            <geometry>
                <mesh filename="package://ardupilot_gz_description/models/learm/meshes/wrist.dae" scale="1 1 1"/>
            </geometry>
            <material name="wrist_linkwrist_link_visual">
                <texture/>
                <color rgba="0.12 0.12 0.12 1.2"/>
            </material>
        </visual>
        <collision>
            <origin xyz="2.77556e-17 0 -5.55112e-17" rpy="0 4.05861e-17 0"/>
            <geometry>
                <mesh filename="package://ardupilot_gz_description/models/learm/meshes/wrist_lowpoly.stl" scale="1 1 1"/>
            </geometry>
        </collision>
    </link>
    <joint name="elbow" type="revolute">
        <origin xyz="-1.38778e-17 0 0.105" rpy="0 2.02931e-17 0"/>
        <axis xyz="0 -1 0"/>
        <parent link="humerus_link"/>
        <child link="forearm_link"/>
        <dynamics damping="0.04" friction="0"/>
        <limit effort="10" velocity="0.5" lower="-1.57" upper="1.57"/>
    </joint>
    <joint name="finger_left" type="revolute">
        <origin xyz="0.006 -1.11022e-16 0.029" rpy="1.57 -2.31183e-18 -1.22229e-16"/>
        <axis xyz="-1 4.57939e-34 2.02931e-17"/>
        <parent link="grip_left_link"/>
        <child link="finger_left_link"/>
        <dynamics damping="0.01" friction="0"/>
        <limit effort="10" velocity="0.5" lower="0" upper="1.57"/>
    </joint>
    <joint name="finger_right" type="revolute">
        <origin xyz="0.008 1.11022e-16 0.03" rpy="-1.57 -2.31183e-18 1.22229e-16"/>
        <axis xyz="1 4.57939e-34 -2.02931e-17"/>
        <parent link="grip_right_link"/>
        <child link="finger_right_link"/>
        <dynamics damping="0.01" friction="0"/>
        <limit effort="10" velocity="0.5" lower="0" upper="1.57"/>
    </joint>
    <joint name="grip_left" type="revolute">
        <origin xyz="-0.006 0.0137 0.0318" rpy="-1.57 6.15908e-17 -4.36179e-17"/>
        <axis xyz="1 4.78263e-17 1.59098e-17"/>
        <parent link="hand_link"/>
        <child link="grip_left_link"/>
        <dynamics damping="0.01" friction="0"/>
        <limit effort="10" velocity="0.5" lower="0" upper="1.57"/>
    </joint>
    <joint name="grip_right" type="revolute">
        <origin xyz="-0.008 -0.0137 0.0315" rpy="1.57 6.15908e-17 4.36179e-17"/>
        <axis xyz="-1 4.78263e-17 -1.59098e-17"/>
        <parent link="hand_link"/>
        <child link="grip_right_link"/>
        <dynamics damping="0.01" friction="0"/>
        <limit effort="10" velocity="0.5" lower="0" upper="1.57"/>
    </joint>
    <joint name="shoulder_lift" type="revolute">
        <origin xyz="-0.01 0 0.028" rpy="0 1.5708 -0"/>
        <axis xyz="0 1 0"/>
        <parent link="shoulder_link"/>
        <child link="humerus_link"/>
        <dynamics damping="0.01" friction="0"/>
        <limit effort="50" velocity="0.5" lower="-3.142" upper="0"/>
    </joint>
    <joint name="shoulder_pan" type="revolute">
        <origin xyz="0 0 0.059" rpy="0 -0 0"/>
        <axis xyz="0 0 1"/>
        <parent link="arm_base_link"/>
        <child link="shoulder_link"/>
        <dynamics damping="0.01" friction="0"/>
        <limit effort="10" velocity="0.5" lower="-1.57" upper="1.57"/>
    </joint>
    <joint name="tendon_left" type="revolute">
        <origin xyz="-5.55112e-17 0.005 0.05" rpy="-1.57 6.15908e-17 -4.36179e-17"/>
        <axis xyz="1 4.78263e-17 1.59098e-17"/>
        <parent link="hand_link"/>
        <child link="tendon_left_link"/>
        <dynamics damping="0.01" friction="0"/>
        <limit effort="10" velocity="0.5" lower="0" upper="1.57"/>
    </joint>
    <joint name="tendon_right" type="revolute">
        <origin xyz="-5.55112e-17 -0.005 0.05" rpy="1.57 6.15908e-17 4.36179e-17"/>
        <axis xyz="-1 4.78263e-17 -1.59098e-17"/>
        <parent link="hand_link"/>
        <child link="tendon_right_link"/>
        <dynamics damping="0.01" friction="0"/>
        <limit effort="10" velocity="0.5" lower="0" upper="1.57"/>
    </joint>
    <joint name="wrist_flex" type="revolute">
        <origin xyz="-1.38778e-17 0 0.09" rpy="0 2.02931e-17 0"/>
        <axis xyz="0 -1 0"/>
        <parent link="forearm_link"/>
        <child link="wrist_link"/>
        <dynamics damping="0.04" friction="0"/>
        <limit effort="10" velocity="0.5" lower="-1.57" upper="1.57"/>
    </joint>
    <joint name="wrist_roll" type="revolute">
        <origin xyz="4.16334e-17 0 0.06" rpy="0 2.02931e-17 0"/>
        <axis xyz="2.02931e-17 0 1"/>
        <parent link="wrist_link"/>
        <child link="hand_link"/>
        <dynamics damping="0.04" friction="0"/>
        <limit effort="10" velocity="0.5" lower="-1.57" upper="1.57"/>
    </joint>
</robot>
